Workbook
Name ListaEstados: Catálogos!$A$2:$A$6
Name ListaTipos: Catálogos!$B$2:$B$6
Name ListaPrioridades: Catálogos!$C$2:$C$5
Name ListaSeveridades: Catálogos!$D$2:$D$6

Sheet Dashboard QA
A1: Dashboard QA — Sprint 1 (Núcleo de Stock)
A2: Se actualiza solo: todos los valores son fórmulas sobre 'Matriz consolidada' y 'Trazabilidad'.
A4: Indicadores principales
A5: Total de historias (Sprint 1) | B5: =COUNTA('Resumen por historia'!$A$2:$A$12)
A6: Total de casos de prueba | B6: =COUNTA('Matriz consolidada'!$A$2:$A$65)
A7: Total de criterios de aceptación | B7: =COUNTA(Trazabilidad!$B$2:$B$48)
A8: Criterios de aceptación cubiertos | B8: =COUNTIF(Trazabilidad!$E$2:$E$48,"Cubierto")
A9: % cobertura de criterios de aceptación | B9: =B8/B7
A10: Casos pendientes | B10: =COUNTIF('Matriz consolidada'!$L$2:$L$65,"Pendiente")
A11: Casos aprobados | B11: =COUNTIF('Matriz consolidada'!$L$2:$L$65,"Aprobado")
A12: Casos fallidos | B12: =COUNTIF('Matriz consolidada'!$L$2:$L$65,"Fallido")
A13: Casos bloqueados | B13: =COUNTIF('Matriz consolidada'!$L$2:$L$65,"Bloqueado")
A15: Distribución por estado
A16: Estado | B16: Cantidad | C16: %
A17: Pendiente | B17: =COUNTIF('Matriz consolidada'!$L$2:$L$65,"Pendiente") | C17: =B17/64
A18: Aprobado | B18: =COUNTIF('Matriz consolidada'!$L$2:$L$65,"Aprobado") | C18: =B18/64
A19: Fallido | B19: =COUNTIF('Matriz consolidada'!$L$2:$L$65,"Fallido") | C19: =B19/64
A20: Bloqueado | B20: =COUNTIF('Matriz consolidada'!$L$2:$L$65,"Bloqueado") | C20: =B20/64
A21: No ejecutado | B21: =COUNTIF('Matriz consolidada'!$L$2:$L$65,"No ejecutado") | C21: =B21/64
A23: Distribución por tipo de prueba
A24: Tipo de prueba | B24: Cantidad | C24: %
A25: Camino feliz | B25: =COUNTIF('Matriz consolidada'!$E$2:$E$65,"Camino feliz") | C25: =B25/64
A26: Validación | B26: =COUNTIF('Matriz consolidada'!$E$2:$E$65,"Validación") | C26: =B26/64
A27: Caso de error | B27: =COUNTIF('Matriz consolidada'!$E$2:$E$65,"Caso de error") | C27: =B27/64
A28: Integración | B28: =COUNTIF('Matriz consolidada'!$E$2:$E$65,"Integración") | C28: =B28/64
A29: Regresión | B29: =COUNTIF('Matriz consolidada'!$E$2:$E$65,"Regresión") | C29: =B29/64
A31: Distribución por prioridad
A32: Prioridad | B32: Cantidad | C32: %
A33: Crítica | B33: =COUNTIF('Matriz consolidada'!$F$2:$F$65,"Crítica") | C33: =B33/64
A34: Alta | B34: =COUNTIF('Matriz consolidada'!$F$2:$F$65,"Alta") | C34: =B34/64
A35: Media | B35: =COUNTIF('Matriz consolidada'!$F$2:$F$65,"Media") | C35: =B35/64
A36: Baja | B36: =COUNTIF('Matriz consolidada'!$F$2:$F$65,"Baja") | C36: =B36/64
A38: Cobertura de criterios de aceptación por historia
A39: Historia | B39: Cobertura CA
A40: ='Resumen por historia'!A2 | B40: ='Resumen por historia'!L2
A41: ='Resumen por historia'!A3 | B41: ='Resumen por historia'!L3
A42: ='Resumen por historia'!A4 | B42: ='Resumen por historia'!L4
A43: ='Resumen por historia'!A5 | B43: ='Resumen por historia'!L5
A44: ='Resumen por historia'!A6 | B44: ='Resumen por historia'!L6
A45: ='Resumen por historia'!A7 | B45: ='Resumen por historia'!L7
...

Sheet Matriz consolidada
A1: ID Caso | B1: Historia | C1: Issue | D1: Criterio de aceptación | E1: Tipo de prueba | F1: Prioridad | G1: Precondiciones | H1: Datos de prueba | I1: Pasos | J1: Resultado esperado | K1: Resultado obtenido | L1: Estado | M1: Severidad | N1: Evidencia | O1: Responsable | P1: Fecha de ejecución | Q1: Defecto asociado | R1: Observaciones
A2: TC-STK-01-01 | B2: US-STK-01 | C2: #6 | D2: CA-01 — El sistema genera un ID único; CA-02 — El nombre es obligatorio; CA-03 — Debe seleccionarse una categoría, marca y unidad de medida existentes y activas; CA-04 — El código de barras no puede estar duplicado | E2: Camino feliz | F2: Crítica | G2: Usuario autenticado con permisos de gestión de artículos; existen una categoría, una marca y una unidad de medida activas. | H2: Nombre: Cemento Portland x50kg | Categoría: Cementos (activa) | Marca: Loma Negra (activa) | Unidad de medida: Bolsa (activa) | Código de barras: 7791234567890 | I2: 1. Ingresar al módulo Artículos. 2. Seleccionar "Nuevo artículo". 3. Completar nombre, categoría, marca y unidad de medida (todas existentes y activas) y un código de barras no utilizado. 4. Presionar "Guardar". | J2: El artículo se crea con un ID único generado por el sistema, queda con estado Activo por defecto, y sus datos (categoría, marca, unidad de medida, código de barras) se guardan tal como se ingresaron. | K2: Pendiente de ejecución | L2: Pendiente | M2: N/A | N2: Pendiente | O2: gonzavillalba02 | P2: — | Q2: N/A | R2: —
A3: TC-STK-01-02 | B3: US-STK-01 | C3: #6 | D3: CA-05 — El estado es Activo o Inactivo | E3: Camino feliz | F3: Media | G3: Existe un artículo con estado Activo. | H3: Artículo existente con estado: Activo → nuevo estado: Inactivo | I3: 1. Ingresar a la ficha del artículo. 2. Cambiar su estado a Inactivo (PATCH estado). 3. Guardar el cambio. | J3: El artículo queda con estado Inactivo y ese cambio se refleja en su ficha y en el listado. | K3: Pendiente de ejecución | L3: Pendiente | M3: N/A | N3: Pendiente | O3: gonzavillalba02 | P3: — | Q3: N/A | R3: —
A4: TC-STK-01-03 | B4: US-STK-01 | C4: #6 | D4: CA-02 — El nombre es obligatorio | E4: Validación | F4: Alta | G4: Usuario en el formulario de alta de artículo, con categoría, marca, unidad de medida y código de barras completos. | H4: Nombre: (vacío) | Categoría: Cementos | Marca: Loma Negra | Unidad: Bolsa | Código de barras: 7791234567891 | I4: 1. Dejar el campo Nombre vacío. 2. Presionar "Guardar". | J4: El sistema rechaza la operación (HTTP 400) e informa que el nombre es obligatorio; el artículo no se crea. | K4: Pendiente de ejecución | L4: Pendiente | M4: N/A | N4: Pendiente | O4: gonzavillalba02 | P4: — | Q4: N/A | R4: —
A5: TC-STK-01-04 | B5: US-STK-01 | C5: #6 | D5: CA-03 — Debe seleccionarse una categoría, marca y unidad de medida existentes y activas | E5: Validación | F5: Alta | G5: Usuario en el formulario de alta de artículo, con el nombre completado. | H5: Nombre: Cemento Portland x50kg | Categoría: (sin seleccionar) | Marca: Loma Negra | Unidad: Bolsa | I5: 1. Dejar sin seleccionar la categoría (o, en pruebas equivalentes, la marca o la unidad de medida). 2. Presionar "Guardar". | J5: El sistema rechaza la operación (HTTP 400) e informa que el campo es obligatorio; el artículo no se crea. | K5: Pendiente de ejecución | L5: Pendiente | M5: N/A | N5: Pendiente | O5: gonzavillalba02 | P5: — | Q5: N/A | R5: —
A6: TC-STK-01-05 | B6: US-STK-01 | C6: #6 | D6: CA-04 — El código de barras no puede estar duplicado | E6: Caso de error | F6: Alta | G6: Ya existe un artículo con código de barras "7791234567890". | H6: Código de barras: 7791234567890 (ya usado por otro artículo) | I6: 1. Completar el formulario de alta de un artículo nuevo con datos válidos. 2. Ingresar el mismo código de barras "7791234567890". 3. Presionar "Guardar". | J6: El sistema rechaza la operación (HTTP 409) e informa que el código de barras ya existe en otro artículo; el artículo no se crea. | K6: Pendiente de ejecución | L6: Pendiente | M6: N/A | N6: Pendiente | O6: gonzavillalba02 | P6: — | Q6: N/A | R6: —
A7: TC-STK-01-06 | B7: US-STK-01 | C7: #6 | D7: CA-03 — Debe seleccionarse una categoría, marca y unidad de medida existentes y activas | E7: Caso de error | F7: Alta | G7: Existe una categoría, marca o unidad de medida inactiva (o se dispone de un ID inexistente para alguna de ellas). | H7: Categoría: id inexistente o categoría marcada Inactiva | I7: 1. Completar el formulario de alta de artículo referenciando esa categoría/marca/unidad de medida inactiva o inexistente. 2. Presionar "Guardar". | J7: El sistema rechaza la operación (HTTP 422) e informa que la referencia no existe o está inactiva; el artículo no se crea. | K7: Pendiente de ejecución | L7: Pendiente | M7: N/A | N7: Pendiente | O7: gonzavillalba02 | P7: — | Q7: N/A | R7: —
A8: TC-STK-02-01 | B8: US-STK-02 | C8: #7 | D8: CA-01 — No pueden existir categorías duplicadas (por nombre); CA-02 — El nombre es obligatorio | E8: Camino feliz | F8: Alta | G8: Usuario autenticado; no existe una categoría con el nombre a utilizar. | H8: Nombre: Cementos | I8: 1. Ingresar al módulo Categorías. 2. Seleccionar "Nueva categoría". 3. Completar un nombre válido y no utilizado. 4. Guardar. | J8: La categoría se crea correctamente y aparece en el listado. | K8: Pendiente de ejecución | L8: Pendiente | M8: N/A | N8: Pendiente | O8: gonzavillalba02 | P8: — | Q8: N/A | R8: —
A9: TC-STK-02-02 | B9: US-STK-02 | C9: #7 | D9: CA-03 — No puede eliminarse una categoría asociada a artículos | E9: Camino feliz | F9: Media | G9: Existe una categoría sin artículos asociados. | H9: Categoría: Herramientas (sin artículos asociados) | I9: 1. Seleccionar la categoría. 2. Elegir "Eliminar". 3. Confirmar la eliminación. | J9: La categoría se elimina correctamente y deja de aparecer en el listado. | K9: Pendiente de ejecución | L9: Pendiente | M9: N/A | N9: Pendiente | O9: gonzavillalba02 | P9: — | Q9: N/A | R9: —
A10: TC-STK-02-03 | B10: US-STK-02 | C10: #7 | D10: CA-02 — El nombre es obligatorio | E10: Validación | F10: Alta | G10: Usuario en el formulario de alta de categoría. | H10: Nombre: (vacío) | I10: 1. Dejar el campo Nombre vacío. 2. Guardar. | J10: El sistema rechaza la operación (HTTP 400) e informa que el nombre es obligatorio. | K10: Pendiente de ejecución | L10: Pendiente | M10: N/A | N10: Pendiente | O10: gonzavillalba02 | P10: — | Q10: N/A | R10: —
A11: TC-STK-02-04 | B11: US-STK-02 | C11: #7 | D11: CA-01 — No pueden existir categorías duplicadas (por nombre) | E11: Caso de error | F11: Alta | G11: Ya existe una categoría con un nombre determinado. | H11: Nombre: Cementos (ya existente) | I11: 1. Intentar crear una nueva categoría usando ese mismo nombre. 2. Guardar. | J11: El sistema rechaza la operación (HTTP 409) e informa que el nombre ya existe. | K11: Pendiente de ejecución | L11: Pendiente | M11: N/A | N11: Pendiente | O11: gonzavillalba02 | P11: — | Q11: N/A | R11: —
A12: TC-STK-02-05 | B12: US-STK-02 | C12: #7 | D12: CA-03 — No puede eliminarse una categoría asociada a artículos | E12: Caso de error | F12: Media | G12: Existe una categoría con al menos un artículo asociado. | H12: Categoría: Cementos (con artículos asociados) | I12: 1. Seleccionar la categoría. 2. Intentar eliminarla. | J12: El sistema rechaza la eliminación (HTTP 409), informa cuántos artículos la usan, y la categoría no se borra. | K12: Pendiente de ejecución | L12: Pendiente | M12: N/A | N12: Pendiente | O12: gonzavillalba02 | P12: — | Q12: N/A | R12: —
... A65: TC-STK-15-05 | B65: US-STK-15 | C65: #17 | D65: Sin CA numerado — deriva de "Casos de error" del issue, no de un criterio de aceptación explícito | E65: Caso de error | F65: Media | G65: Existe una alerta que ya fue atendida previamente. | H65: Alerta en estado: ya atendida | I65: 1. Intentar atender esa misma alerta nuevamente. | J65: El sistema rechaza la operación (HTTP 409) e informa que la alerta ya fue atendida. | K65: Pendiente de ejecución | L65: Pendiente | M65: N/A | N65: Pendiente | O65: carmelaserrano | P65: — | Q65: N/A | R65: —

Sheet Resumen por historia
A1: Historia | B1: Issue | C1: Título | D1: Responsable | E1: Total TC | F1: Camino feliz | G1: Casos de error | H1: Pendientes | I1: Aprobados | J1: Fallidos | K1: Bloqueados | L1: Cobertura CA
A2: US-STK-01 | B2: #6 | C2: Alta y gestión de artículos | D2: gonzavillalba02 | E2: =COUNTIF('Matriz consolidada'!$B$2:$B$65,$A2) | F2: =COUNTIFS('Matriz consolidada'!$B$2:$B$65,$A2,'Matriz consolidada'!$E$2:$E$65,"Camino feliz") | G2: =COUNTIFS('Matriz consolidada'!$B$2:$B$65,$A2,'Matriz consolidada'!$E$2:$E$65,"Caso de error") | H2: =COUNTIFS('Matriz consolidada'!$B$2:$B$65,$A2,'Matriz consolidada'!$L$2:$L$65,"Pendiente") | I2: =COUNTIFS('Matriz consolidada'!$B$2:$B$65,$A2,'Matriz consolidada'!$L$2:$L$65,"Aprobado") | J2: =COUNTIFS('Matriz consolidada'!$B$2:$B$65,$A2,'Matriz consolidada'!$L$2:$L$65,"Fallido") | K2: =COUNTIFS('Matriz consolidada'!$B$2:$B$65,$A2,'Matriz consolidada'!$L$2:$L$65,"Bloqueado") | L2: =COUNTIFS('Trazabilidad'!$A$2:$A$48,$A2,'Trazabilidad'!$E$2:$E$48,"Cubierto")/COUNTIF('Trazabilidad'!$A$2:$A$48,$A2)
A3: US-STK-02 | B3: #7 | C3: Gestión de categorías | D3: gonzavillalba02 | E3: =COUNTIF('Matriz consolidada'!$B$2:$B$65,$A3) | F3: =COUNTIFS('Matriz consolidada'!$B$2:$B$65,$A3,'Matriz consolidada'!$E$2:$E$65,"Camino feliz") | G3: =COUNTIFS('Matriz consolidada'!$B$2:$B$65,$A3,'Matriz consolidada'!$E$2:$E$65,"Caso de error") | H3: =COUNTIFS('Matriz consolidada'!$B$2:$B$65,$A3,'Matriz consolidada'!$L$2:$L$65,"Pendiente") | I3: =COUNTIFS('Matriz consolidada'!$B$2:$B$65,$A3,'Matriz consolidada'!$L$2:$L$65,"Aprobado") | J3: =COUNTIFS('Matriz consolidada'!$B$2:$B$65,$A3,'Matriz consolidada'!$L$2:$L$65,"Fallido") | K3: =COUNTIFS('Matriz consolidada'!$B$2:$B$65,$A3,'Matriz consolidada'!$L$2:$L$65,"Bloqueado") | L3: =COUNTIFS('Trazabilidad'!$A$2:$A$48,$A3,'Trazabilidad'!$E$2:$E$48,"Cubierto")/COUNTIF('Trazabilidad'!$A$2:$A$48,$A3)
A4: US-STK-03 | B4: #8 | C4: Gestión de marcas | D4: gonzavillalba02 | E4: =COUNTIF('Matriz consolidada'!$B$2:$B$65,$A4) | F4: =COUNTIFS('Matriz consolidada'!$B$2:$B$65,$A4,'Matriz consolidada'!$E$2:$E$65,"Camino feliz") | G4: =COUNTIFS('Matriz consolidada'!$B$2:$B$65,$A4,'Matriz consolidada'!$E$2:$E$65,"Caso de error") | H4: =COUNTIFS('Matriz consolidada'!$B$2:$B$65,$A4,'Matriz consolidada'!$L$2:$L$65,"Pendiente") | I4: =COUNTIFS('Matriz consolidada'!$B$2:$B$65,$A4,'Matriz consolidada'!$L$2:$L$65,"Aprobado") | J4: =COUNTIFS('Matriz consolidada'!$B$2:$B$65,$A4,'Matriz consolidada'!$L$2:$L$65,"Fallido") | K4: =COUNTIFS('Matriz consolidada'!$B$2:$B$65,$A4,'Matriz consolidada'!$L$2:$L$65,"Bloqueado") | L4: =COUNTIFS('Trazabilidad'!$A$2:$A$48,$A4,'Trazabilidad'!$E$2:$E$48,"Cubierto")/COUNTIF('Trazabilidad'!$A$2:$A$48,$A4)
A5: US-STK-04 | B5: #9 | C5: Gestión de unidades de medida | D5: gonzavillalba02 | E5: =COUNTIF('Matriz consolidada'!$B$2:$B$65,$A5) | F5: =COUNTIFS('Matriz consolidada'!$B$2:$B$65,$A5,'Matriz consolidada'!$E$2:$E$65,"Camino feliz") | G5: =COUNTIFS('Matriz consolidada'!$B$2:$B$65,$A5,'Matriz consolidada'!$E$2:$E$65,"Caso de error") | H5: =COUNTIFS('Matriz consolidada'!$B$2:$B$65,$A5,'Matriz consolidada'!$L$2:$L$65,"Pendiente") | I5: =COUNTIFS('Matriz consolidada'!$B$2:$B$65,$A5,'Matriz consolidada'!$L$2:$L$65,"Aprobado") | J5: =COUNTIFS('Matriz consolidada'!$B$2:$B$65,$A5,'Matriz consolidada'!$L$2:$L$65,"Fallido") | K5: =COUNTIFS('Matriz consolidada'!$B$2:$B$65,$A5,'Matriz consolidada'!$L$2:$L$65,"Bloqueado") | L5: =COUNTIFS('Trazabilidad'!$A$2:$A$48,$A5,'Trazabilidad'!$E$2:$E$48,"Cubierto")/COUNTIF('Trazabilidad'!$A$2:$A$48,$A5)
A6: US-STK-05 | B6: #10 | C6: Gestión de depósitos | D6: TomasT04 | E6: =COUNTIF('Matriz consolidada'!$B$2:$B$65,$A6) | F6: =COUNTIFS('Matriz consolidada'!$B$2:$B$65,$A6,'Matriz consolidada'!$E$2:$E$65,"Camino feliz") | G6: =COUNTIFS('Matriz consolidada'!$B$2:$B$65,$A6,'Matriz consolidada'!$E$2:$E$65,"Caso de error") | H6: =COUNTIFS('Matriz consolidada'!$B$2:$B$65,$A6,'Matriz consolidada'!$L$2:$L$65,"Pendiente") | I6: =COUNTIFS('Matriz consolidada'!$B$2:$B$65,$A6,'Matriz consolidada'!$L$2:$L$65,"Aprobado") | J6: =COUNTIFS('Matriz consolidada'!$B$2:$B$65,$A6,'Matriz consolidada'!$L$2:$L$65,"Fallido") | K6: =COUNTIFS('Matriz consolidada'!$B$2:$B$65,$A6,'Matriz consolidada'!$L$2:$L$65,"Bloqueado") | L6: =COUNTIFS('Trazabilidad'!$A$2:$A$48,$A6,'Trazabilidad'!$E$2:$E$48,"Cubierto")/COUNTIF('Trazabilidad'!$A$2:$A$48,$A6)
A7: US-STK-06 | B7: #11 | C7: Configuración de stock por depósito (mínimo y máximo) | D7: TomasT04 | E7: =COUNTIF('Matriz consolidada'!$B$2:$B$65,$A7) | F7: =COUNTIFS('Matriz consolidada'!$B$2:$B$65,$A7,'Matriz consolidada'!$E$2:$E$65,"Camino feliz") | G7: =COUNTIFS('Matriz consolidada'!$B$2:$B$65,$A7,'Matriz consolidada'!$E$2:$E$65,"Caso de error") | H7: =COUNTIFS('Matriz consolidada'!$B$2:$B$65,$A7,'Matriz consolidada'!$L$2:$L$65,"Pendiente") | I7: =COUNTIFS('Matriz consolidada'!$B$2:$B$65,$A7,'Matriz consolidada'!$L$2:$L$65,"Aprobado") | J7: =COUNTIFS('Matriz consolidada'!$B$2:$B$65,$A7,'Matriz consolidada'!$L$2:$L$65,"Fallido") | K7: =COUNTIFS('Matriz consolidada'!$B$2:$B$65,$A7,'Matriz consolidada'!$L$2:$L$65,"Bloqueado") | L7: =COUNTIFS('Trazabilidad'!$A$2:$A$48,$A7,'Trazabilidad'!$E$2:$E$48,"Cubierto")/COUNTIF('Trazabilidad'!$A$2:$A$48,$A7)
A8: US-STK-07 | B8: #12 | C8: Consulta de stock en tiempo real | D8: sanz05 | E8: =COUNTIF('Matriz consolidada'!$B$2:$B$65,$A8) | F8: =COUNTIFS('Matriz consolidada'!$B$2:$B$65,$A8,'Matriz consolidada'!$E$2:$E$65,"Camino feliz") | G8: =COUNTIFS('Matriz consolidada'!$B$2:$B$65,$A8,'Matriz consolidada'!$E$2:$E$65,"Caso de error") | H8: =COUNTIFS('Matriz consolidada'!$B$2:$B$65,$A8,'Matriz consolidada'!$L$2:$L$65,"Pendiente") | I8: =COUNTIFS('Matriz consolidada'!$B$2:$B$65,$A8,'Matriz consolidada'!$L$2:$L$65,"Aprobado") | J8: =COUNTIFS('Matriz consolidada'!$B$2:$B$65,$A8,'Matriz consolidada'!$L$2:$L$65,"Fallido") | K8: =COUNTIFS('Matriz consolidada'!$B$2:$B$65,$A8,'Matriz consolidada'!$L$2:$L$65,"Bloqueado") | L8: =COUNTIFS('Trazabilidad'!$A$2:$A$48,$A8,'Trazabilidad'!$E$2:$E$48,"Cubierto")/COUNTIF('Trazabilidad'!$A$2:$A$48,$A8)
A9: US-STK-08 | B9: #13 | C9: Registro de movimientos de stock | D9: mateoquartin | E9: =COUNTIF('Matriz consolidada'!$B$2:$B$65,$A9) | F9: =COUNTIFS('Matriz consolidada'!$B$2:$B$65,$A9,'Matriz consolidada'!$E$2:$E$65,"Camino feliz") | G9: =COUNTIFS('Matriz consolidada'!$B$2:$B$65,$A9,'Matriz consolidada'!$E$2:$E$65,"Caso de error") | H9: =COUNTIFS('Matriz consolidada'!$B$2:$B$65,$A9,'Matriz consolidada'!$L$2:$L$65,"Pendiente") | I9: =COUNTIFS('Matriz consolidada'!$B$2:$B$65,$A9,'Matriz consolidada'!$L$2:$L$65,"Aprobado") | J9: =COUNTIFS('Matriz consolidada'!$B$2:$B$65,$A9,'Matriz consolidada'!$L$2:$L$65,"Fallido") | K9: =COUNTIFS('Matriz consolidada'!$B$2:$B$65,$A9,'Matriz consolidada'!$L$2:$L$65,"Bloqueado") | L9: =COUNTIFS('Trazabilidad'!$A$2:$A$48,$A9,'Trazabilidad'!$E$2:$E$48,"Cubierto")/COUNTIF('Trazabilidad'!$A$2:$A$48,$A9)
A10: US-STK-09 | B10: #15 | C10: Confirmación de recepción de mercadería | D10: mateoquartin | E10: =COUNTIF('Matriz consolidada'!$B$2:$B$65,$A10) | F10: =COUNTIFS('Matriz consolidada'!$B$2:$B$65,$A10,'Matriz consolidada'!$E$2:$E$65,"Camino feliz") | G10: =COUNTIFS('Matriz consolidada'!$B$2:$B$65,$A10,'Matriz consolidada'!$E$2:$E$65,"Caso de error") | H10: =COUNTIFS('Matriz consolidada'!$B$2:$B$65,$A10,'Matriz consolidada'!$L$2:$L$65,"Pendiente") | I10: =COUNTIFS('Matriz consolidada'!$B$2:$B$65,$A10,'Matriz consolidada'!$L$2:$L$65,"Aprobado") | J10: =COUNTIFS('Matriz consolidada'!$B$2:$B$65,$A10,'Matriz consolidada'!$L$2:$L$65,"Fallido") | K10: =COUNTIFS('Matriz consolidada'!$B$2:$B$65,$A10,'Matriz consolidada'!$L$2:$L$65,"Bloqueado") | L10: =COUNTIFS('Trazabilidad'!$A$2:$A$48,$A10,'Trazabilidad'!$E$2:$E$48,"Cubierto")/COUNTIF('Trazabilidad'!$A$2:$A$48,$A10)
A11: US-STK-13 | B11: #16 | C11: Valorización de inventario y costo medio ponderado | D11: carmelaserrano | E11: =COUNTIF('Matriz consolidada'!$B$2:$B$65,$A11) | F11: =COUNTIFS('Matriz consolidada'!$B$2:$B$65,$A11,'Matriz consolidada'!$E$2:$E$65,"Camino feliz") | G11: =COUNTIFS('Matriz consolidada'!$B$2:$B$65,$A11,'Matriz consolidada'!$E$2:$E$65,"Caso de error") | H11: =COUNTIFS('Matriz consolidada'!$B$2:$B$65,$A11,'Matriz consolidada'!$L$2:$L$65,"Pendiente") | I11: =COUNTIFS('Matriz consolidada'!$B$2:$B$65,$A11,'Matriz consolidada'!$L$2:$L$65,"Aprobado") | J11: =COUNTIFS('Matriz consolidada'!$B$2:$B$65,$A11,'Matriz consolidada'!$L$2:$L$65,"Fallido") | K11: =COUNTIFS('Matriz consolidada'!$B$2:$B$65,$A11,'Matriz consolidada'!$L$2:$L$65,"Bloqueado") | L11: =COUNTIFS('Trazabilidad'!$A$2:$A$48,$A11,'Trazabilidad'!$E$2:$E$48,"Cubierto")/COUNTIF('Trazabilidad'!$A$2:$A$48,$A11)
A12: US-STK-15 | B12: #17 | C12: Alertas de stock mínimo (in-app y email) | D12: carmelaserrano | E12: =COUNTIF('Matriz consolidada'!$B$2:$B$65,$A12) | F12: =COUNTIFS('Matriz consolidada'!$B$2:$B$65,$A12,'Matriz consolidada'!$E$2:$E$65,"Camino feliz") | G12: =COUNTIFS('Matriz consolidada'!$B$2:$B$65,$A12,'Matriz consolidada'!$E$2:$E$65,"Caso de error") | H12: =COUNTIFS('Matriz consolidada'!$B$2:$B$65,$A12,'Matriz consolidada'!$L$2:$L$65,"Pendiente") | I12: =COUNTIFS('Matriz consolidada'!$B$2:$B$65,$A12,'Matriz consolidada'!$L$2:$L$65,"Aprobado") | J12: =COUNTIFS('Matriz consolidada'!$B$2:$B$65,$A12,'Matriz consolidada'!$L$2:$L$65,"Fallido") | K12: =COUNTIFS('Matriz consolidada'!$B$2:$B$65,$A12,'Matriz consolidada'!$L$2:$L$65,"Bloqueado") | L12: =COUNTIFS('Trazabilidad'!$A$2:$A$48,$A12,'Trazabilidad'!$E$2:$E$48,"Cubierto")/COUNTIF('Trazabilidad'!$A$2:$A$48,$A12)
A13: TOTAL | E13: =SUM(E2:E12) | F13: =SUM(F2:F12) | G13: =SUM(G2:G12) | H13: =SUM(H2:H12) | I13: =SUM(I2:I12) | J13: =SUM(J2:J12) | K13: =SUM(K2:K12) | L13: =COUNTIF('Trazabilidad'!$E$2:$E$48,"Cubierto")/COUNTA('Trazabilidad'!$E$2:$E$48)

Sheet Trazabilidad
A1: Historia | B1: Criterio de aceptación | C1: Descripción | D1: Casos de prueba | E1: Cobertura
A2: US-STK-01 | B2: CA-01 | C2: El sistema genera un ID único | D2: TC-STK-01-01 | E2: =IF(D2="(sin casos)","No cubierto","Cubierto")
A3: US-STK-01 | B3: CA-02 | C3: El nombre es obligatorio | D3: TC-STK-01-01, TC-STK-01-03 | E3: =IF(D3="(sin casos)","No cubierto","Cubierto")
A4: US-STK-01 | B4: CA-03 | C4: Debe seleccionarse una categoría, marca y unidad de medida existentes y activas | D4: TC-STK-01-01, TC-STK-01-04, TC-STK-01-06 | E4: =IF(D4="(sin casos)","No cubierto","Cubierto")
A5: US-STK-01 | B5: CA-04 | C5: El código de barras no puede estar duplicado | D5: TC-STK-01-01, TC-STK-01-05 | E5: =IF(D5="(sin casos)","No cubierto","Cubierto")
A6: US-STK-01 | B6: CA-05 | C6: El estado es Activo o Inactivo | D6: TC-STK-01-02 | E6: =IF(D6="(sin casos)","No cubierto","Cubierto")
A7: US-STK-02 | B7: CA-01 | C7: No pueden existir categorías duplicadas (por nombre) | D7: TC-STK-02-01, TC-STK-02-04 | E7: =IF(D7="(sin casos)","No cubierto","Cubierto")
A8: US-STK-02 | B8: CA-02 | C8: El nombre es obligatorio | D8: TC-STK-02-01, TC-STK-02-03 | E8: =IF(D8="(sin casos)","No cubierto","Cubierto")
A9: US-STK-02 | B9: CA-03 | C9: No puede eliminarse una categoría asociada a artículos | D9: TC-STK-02-02, TC-STK-02-05 | E9: =IF(D9="(sin casos)","No cubierto","Cubierto")
A10: US-STK-03 | B10: CA-01 | C10: No pueden existir marcas duplicadas | D10: TC-STK-03-01, TC-STK-03-04 | E10: =IF(D10="(sin casos)","No cubierto","Cubierto")
A11: US-STK-03 | B11: CA-02 | C11: El nombre es obligatorio | D11: TC-STK-03-01, TC-STK-03-03 | E11: =IF(D11="(sin casos)","No cubierto","Cubierto")
A12: US-STK-03 | B12: CA-03 | C12: No puede eliminarse una marca asociada a artículos | D12: TC-STK-03-02, TC-STK-03-05 | E12: =IF(D12="(sin casos)","No cubierto","Cubierto")
A13: US-STK-04 | B13: CA-01 | C13: No pueden existir unidades duplicadas | D13: TC-STK-04-01, TC-STK-04-03 | E13: =IF(D13="(sin casos)","No cubierto","Cubierto")
... A48: US-STK-15 | B48: CA-03 | C48: Los artículos afectados se listan con prioridad en el dashboard gerencial | D48: TC-STK-15-03 | E48: =IF(D48="(sin casos)","No cubierto","Cubierto")

Sheet Catálogos
A1: Estado | B1: Tipo de prueba | C1: Prioridad | D1: Severidad
A2: Pendiente | B2: Camino feliz | C2: Crítica | D2: Crítica
A3: Aprobado | B3: Validación | C3: Alta | D3: Alta
A4: Fallido | B4: Caso de error | C4: Media | D4: Media
A5: Bloqueado | B5: Integración | C5: Baja | D5: Baja
A6: No ejecutado | B6: Regresión | D6: N/A
